Exception on /login [POST]
Traceback (most recent call last):
  File "/usr/local/lib/python3.7/site-packages/sqlalchemy/engine/base.py", line 2276, in _wrap_pool_connect
    return fn()
  File "/usr/local/lib/python3.7/site-packages/sqlalchemy/pool/base.py", line 363, in connect
    return _ConnectionFairy._checkout(self)
  File "/usr/local/lib/python3.7/site-packages/sqlalchemy/pool/base.py", line 773, in _checkout
    fairy = _ConnectionRecord.checkout(pool)
  File "/usr/local/lib/python3.7/site-packages/sqlalchemy/pool/base.py", line 492, in checkout
    rec = pool._do_get()
  File "/usr/local/lib/python3.7/site-packages/sqlalchemy/pool/impl.py", line 139, in _do_get
    self._dec_overflow()
  File "/usr/local/lib/python3.7/site-packages/sqlalchemy/util/langhelpers.py", line 68, in __exit__
    compat.reraise(exc_type, exc_value, exc_tb)
  File "/usr/local/lib/python3.7/site-packages/sqlalchemy/util/compat.py", line 153, in reraise
    raise value
  File "/usr/local/lib/python3.7/site-packages/sqlalchemy/pool/impl.py", line 136, in _do_get
    return self._create_connection()
  File "/usr/local/lib/python3.7/site-packages/sqlalchemy/pool/base.py", line 308, in _create_connection
    return _ConnectionRecord(self)
  File "/usr/local/lib/python3.7/site-packages/sqlalchemy/pool/base.py", line 437, in __init__
    self.__connect(first_connect_check=True)
  File "/usr/local/lib/python3.7/site-packages/sqlalchemy/pool/base.py", line 652, in __connect
    connection = pool._invoke_creator(self)
  File "/usr/local/lib/python3.7/site-packages/sqlalchemy/engine/strategies.py", line 114, in connect
    return dialect.connect(*cargs, **cparams)
  File "/usr/local/lib/python3.7/site-packages/sqlalchemy/engine/default.py", line 489, in connect
    return self.dbapi.connect(*cargs, **cparams)
pyodbc.Error: ('01000', "[01000] [unixODBC][Driver Manager]Can't open lib 'ODBC Driver 17 for SQL Server' : file not found (0) (SQLDriverConnect)")

The above exception was the direct cause of the following exception:

Traceback (most recent call last):
  File "/usr/local/lib/python3.7/site-packages/flask/app.py", line 1982, in wsgi_app
    response = self.full_dispatch_request()
  File "/usr/local/lib/python3.7/site-packages/flask/app.py", line 1614, in full_dispatch_request
    rv = self.handle_user_exception(e)
  File "/usr/local/lib/python3.7/site-packages/flask/app.py", line 1517, in handle_user_exception
    reraise(exc_type, exc_value, tb)
  File "/usr/local/lib/python3.7/site-packages/flask/_compat.py", line 33, in reraise
    raise value
  File "/usr/local/lib/python3.7/site-packages/flask/app.py", line 1612, in full_dispatch_request
    rv = self.dispatch_request()
  File "/usr/local/lib/python3.7/site-packages/flask/app.py", line 1598, in dispatch_request
    return self.view_functions[rule.endpoint](**req.view_args)
  File "/Users/pilalouis/Desktop/Security/Development/Azure/nd081-c1-provisioning-microsoft-azure-vms-project-starter/FlaskWebProject/views.py", line 72, in login
    user = User.query.filter_by(username=form.username.data).first()
  File "/usr/local/lib/python3.7/site-packages/sqlalchemy/orm/query.py", line 3287, in first
    ret = list(self[0:1])
  File "/usr/local/lib/python3.7/site-packages/sqlalchemy/orm/query.py", line 3065, in __getitem__
    return list(res)
  File "/usr/local/lib/python3.7/site-packages/sqlalchemy/orm/query.py", line 3389, in __iter__
    return self._execute_and_instances(context)
  File "/usr/local/lib/python3.7/site-packages/sqlalchemy/orm/query.py", line 3411, in _execute_and_instances
    querycontext, self._connection_from_session, close_with_result=True
  File "/usr/local/lib/python3.7/site-packages/sqlalchemy/orm/query.py", line 3426, in _get_bind_args
    mapper=self._bind_mapper(), clause=querycontext.statement, **kw
  File "/usr/local/lib/python3.7/site-packages/sqlalchemy/orm/query.py", line 3404, in _connection_from_session
    conn = self.session.connection(**kw)
  File "/usr/local/lib/python3.7/site-packages/sqlalchemy/orm/session.py", line 1133, in connection
    execution_options=execution_options,
  File "/usr/local/lib/python3.7/site-packages/sqlalchemy/orm/session.py", line 1139, in _connection_for_bind
    engine, execution_options
  File "/usr/local/lib/python3.7/site-packages/sqlalchemy/orm/session.py", line 432, in _connection_for_bind
    conn = bind._contextual_connect()
  File "/usr/local/lib/python3.7/site-packages/sqlalchemy/engine/base.py", line 2242, in _contextual_connect
    self._wrap_pool_connect(self.pool.connect, None),
  File "/usr/local/lib/python3.7/site-packages/sqlalchemy/engine/base.py", line 2280, in _wrap_pool_connect
    e, dialect, self
  File "/usr/local/lib/python3.7/site-packages/sqlalchemy/engine/base.py", line 1547, in _handle_dbapi_exception_noconnection
    util.raise_from_cause(sqlalchemy_exception, exc_info)
  File "/usr/local/lib/python3.7/site-packages/sqlalchemy/util/compat.py", line 398, in raise_from_cause
    reraise(type(exception), exception, tb=exc_tb, cause=cause)
  File "/usr/local/lib/python3.7/site-packages/sqlalchemy/util/compat.py", line 152, in reraise
    raise value.with_traceback(tb)
  File "/usr/local/lib/python3.7/site-packages/sqlalchemy/engine/base.py", line 2276, in _wrap_pool_connect
    return fn()
  File "/usr/local/lib/python3.7/site-packages/sqlalchemy/pool/base.py", line 363, in connect
    return _ConnectionFairy._checkout(self)
  File "/usr/local/lib/python3.7/site-packages/sqlalchemy/pool/base.py", line 773, in _checkout
    fairy = _ConnectionRecord.checkout(pool)
  File "/usr/local/lib/python3.7/site-packages/sqlalchemy/pool/base.py", line 492, in checkout
    rec = pool._do_get()
  File "/usr/local/lib/python3.7/site-packages/sqlalchemy/pool/impl.py", line 139, in _do_get
    self._dec_overflow()
  File "/usr/local/lib/python3.7/site-packages/sqlalchemy/util/langhelpers.py", line 68, in __exit__
    compat.reraise(exc_type, exc_value, exc_tb)
  File "/usr/local/lib/python3.7/site-packages/sqlalchemy/util/compat.py", line 153, in reraise
    raise value
  File "/usr/local/lib/python3.7/site-packages/sqlalchemy/pool/impl.py", line 136, in _do_get
    return self._create_connection()
  File "/usr/local/lib/python3.7/site-packages/sqlalchemy/pool/base.py", line 308, in _create_connection
    return _ConnectionRecord(self)
  File "/usr/local/lib/python3.7/site-packages/sqlalchemy/pool/base.py", line 437, in __init__
    self.__connect(first_connect_check=True)
  File "/usr/local/lib/python3.7/site-packages/sqlalchemy/pool/base.py", line 652, in __connect
    connection = pool._invoke_creator(self)
  File "/usr/local/lib/python3.7/site-packages/sqlalchemy/engine/strategies.py", line 114, in connect
    return dialect.connect(*cargs, **cparams)
  File "/usr/local/lib/python3.7/site-packages/sqlalchemy/engine/default.py", line 489, in connect
    return self.dbapi.connect(*cargs, **cparams)
sqlalchemy.exc.DBAPIError: (pyodbc.Error) ('01000', "[01000] [unixODBC][Driver Manager]Can't open lib 'ODBC Driver 17 for SQL Server' : file not found (0) (SQLDriverConnect)")
(Background on this error at: http://sqlalche.me/e/dbapi)
